// Important note: This is not how error handling is intended to be done in Fae
// This is a contrived program intended to test generic enums

fn divide(value: i32, by: i32): Enum<i32, str> {
	if by == 0 => return .Error { value: "Divide by zero" }
	return .Ok { value: value / by }
}

fn main() {
	match divide(4, 0) {
		result: Ok {
			println(f"{result.value}")
		}

		error: Error => print_error<i32>(error)
	}

	let result = divide(4, 0)
	if result is Ok {
		println(f"{result.value}")
	} else if result is error: Error {
		print_error<i32>(error)
	}

	match divide(4, 2) {
		result: Ok {
			println(f"{result.value}")
		}

		error: Error => print_error<i32>(error)
	}

	let result = divide(4, 2)
	if result is Ok {
		println(f"{result.value}")
	} else if result is error: Error {
		print_error<i32>(error)
	}
}

generic T, E
enum Enum {
	Ok { value: T }
	Error { value: E }
}

generic T
fn print_error(arg: Enum<T, str>.Error) {
	println(f"Error: {arg.value}")
}
